Error output test
Traceback (most recent call last):
  File "/data/users1/mdoan4/wirehead/paper/multigpu_gen/gen/worker.py", line 154, in <module>
    wirehead_manager.run_manager()
  File "/data/users1/mdoan4/wirehead/wirehead/manager.py", line 50, in run_manager
    generated = self.watch_and_swap(generated)
  File "/data/users1/mdoan4/wirehead/wirehead/manager.py", line 116, in watch_and_swap
    return self.swap(generated)    # swap
  File "/data/users1/mdoan4/wirehead/wirehead/manager.py", line 94, in swap
    self.db[self.collectionw].rename(self.collectiont, dropTarget=True)
  File "/data/users1/mdoan4/wirehead/paper/train/wirehead/lib/python3.8/site-packages/pymongo/_csot.py", line 108, in csot_wrapper
    return func(self, *args, **kwargs)
  File "/data/users1/mdoan4/wirehead/paper/train/wirehead/lib/python3.8/site-packages/pymongo/collection.py", line 2948, in rename
    return conn.command(
  File "/data/users1/mdoan4/wirehead/paper/train/wirehead/lib/python3.8/site-packages/pymongo/helpers.py", line 342, in inner
    return func(*args, **kwargs)
  File "/data/users1/mdoan4/wirehead/paper/train/wirehead/lib/python3.8/site-packages/pymongo/pool.py", line 988, in command
    return command(
  File "/data/users1/mdoan4/wirehead/paper/train/wirehead/lib/python3.8/site-packages/pymongo/network.py", line 212, in command
    helpers._check_command_response(
  File "/data/users1/mdoan4/wirehead/paper/train/wirehead/lib/python3.8/site-packages/pymongo/helpers.py", line 248, in _check_command_response
    raise OperationFailure(errmsg, code, response, max_wire_version)
pymongo.errors.OperationFailure: Source collection wirehead_benchmark_multigpu_gen.write.bin does not exist, full error: {'ok': 0.0, 'errmsg': 'Source collection wirehead_benchmark_multigpu_gen.write.bin does not exist', 'code': 26, 'codeName': 'NamespaceNotFound'}
